<mujoco model="pdd_mjx">
  <compiler angle="radian" meshdir="meshes/"/>
  <option timestep='0.002' iterations='50' solver='CG' gravity='0 0 -9.81'>
    <!-- <flag sensornoise="enable" frictionloss="enable" /> -->
  </option>
  <size njmax="500" nconmax="100" />

  <visual>
    <quality shadowsize='4096' />
    <map znear='0.05' />
  </visual>

  <default>
    <default class="hunter">
      <joint damping="1" armature="0.1"/>
      <default class="visual">
        <geom type="mesh" contype="0" conaffinity="0" group="1" density="0" rgba="0.75294 0.75294 0.75294 1"/>
      </default>
      <default class="collision">
        <geom group="3" mass="0" density="0"/>
        <default class="foot">
          <geom type="sphere" size=".001"/>
          <default class="foot1">
            <geom size="0.001" contype="0" conaffinity="0" density="0"/>
          </default>
          <default class="foot2">
            <geom size="0.001"/>
          </default>
        </default>
      </default>
      <site size="0.001" rgba="0.5 0.5 0.5 0.3" group="4"/>
    </default>
    <default class="hunter_motor">
      <motor gear="1" ctrllimited="true" ctrlrange="-100  100" />
    </default>
  </default>

  <asset>
    <texture type="skybox" builtin="gradient" rgb1="0.3 0.5 0.7" rgb2="0 0 0" width="512"
      height="512" />
    <texture name="texplane" type="2d" builtin="checker" rgb1=".2 .3 .4" rgb2=".1 0.15 0.2"
      width="512" height="512" mark="cross" markrgb=".8 .8 .8" />
    <texture name="texplane2" type="2d" builtin="checker" rgb1="1 0.3137 0.1843"
      rgb2="0.0 0.30196 0.38039"
      width="512" height="512" mark="cross" markrgb=".8 .8 .8" />

    <material name="matplane" reflectance="0." texture="texplane" texrepeat="1 1" texuniform="true" />
    <material name="matplane2" reflectance="0.1" texture="texplane2" texrepeat="1 1"
      texuniform="true" />

    <material name='obstacle' rgba='0.9 0.6 0.2 1' />
    <material name='visualgeom' rgba='0.5 0.9 0.2 1' />
    <material name='visualgeom2' rgba='0.5 0.9 0.2 1' />

    <mesh name="base_link" file="base_link.STL" />
    <mesh name="leg_l1_link" file="leg_l1_link.STL" />
    <mesh name="leg_l2_link" file="leg_l2_link.STL" />
    <mesh name="leg_l3_link" file="leg_l3_link.STL" />
    <mesh name="leg_l4_link" file="leg_l4_link.STL" />
    <mesh name="leg_l5_link" file="leg_l5_link.STL" />
    <mesh name="leg_r1_link" file="leg_r1_link.STL" />
    <mesh name="leg_r2_link" file="leg_r2_link.STL" />
    <mesh name="leg_r3_link" file="leg_r3_link.STL" />
    <mesh name="leg_r4_link" file="leg_r4_link.STL" />
    <mesh name="leg_r5_link" file="leg_r5_link.STL" />

    <hfield name='hf0' nrow='200' ncol='200' size="10 5 0.2 .1" />
  </asset>
  <worldbody>
    <light directional="true" diffuse=".4 .4 .4" specular="0.1 0.1 0.1" pos="0 0 5.0" dir="0 0 -1"
      castshadow="false" />
    <light directional="true" diffuse=".6 .6 .6" specular="0.2 0.2 0.2" pos="0 0 4" dir="0 0 -1" />
    <geom name="ground" type="plane" size="0 0 1" pos="0.001 0 0" quat="1 0 0 0" material="matplane"
      condim="1" conaffinity='15' />

    <body name="base_link" pos="0 0 0.7" childclass="hunter">
      <inertial pos="-0.010856 -6.8e-05 -0.007128" quat="0.979606 0.00882716 0.200723 -0.00231074" mass="5.67363" 
      	diaginertia="0.0355096 0.0296524 0.0283549"/>
      <freejoint/>
      <geom class="visual" mesh="base_link"/>
      <geom class="collision" size="0.092 0.075 0.1" pos="-0.01 0 -0.006" type="box"/>
      <!-- <body name="imu_link">
        <inertial pos="0 0 0" mass="0.01" diaginertia="1e-06 1e-06 1e-06"/>
        <geom size="0.0075 0.0075 0.002" type="box" contype="0" conaffinity="0" group="1" density="0"/>
      </body> -->
      <site name="imu" pos="0 0 0"/>
      <body name="leg_l1_link" pos="-0.002 0.09 -0.1035">
        <inertial pos="0.002501 5.3e-05 -0.002722" quat="0.472677 0.527005 0.495251 0.503556" mass="0.453728" 
          diaginertia="0.000163063 0.000147076 8.18618e-05"/>
        <joint name="leg_l1_joint" pos="0 0 0" axis="1 0 0" range="-0.2 0.5" frictionloss="0.2"/>
        <geom class="visual" mesh="leg_l1_link"/>
        <geom class="collision" type="box" size="0.03 0.035 0.0775" pos="-0.019 -0.001 0" quat="0.500398 0.5 0.499602 0.5"/>
        <body name="leg_l2_link" pos="0 -0.00016972 -0.0325">
          <inertial pos="-0.000273 0.043826 -0.058639" quat="0.7074 0.0648812 -0.0612384 0.70116" mass="0.925998" 
            diaginertia="0.00166463 0.00123897 0.0010754"/>
          <joint name="leg_l2_joint" pos="0 0 0" axis="0 0 1" range="-0.5 1" frictionloss="0.2"/>
          <geom class="visual" mesh="leg_l2_link"/>
          <geom class="collision" size="0.065 0.073 0.073" pos="0 0.0046 -0.057" quat="0.707388 0.706825 0 0" type="box" />
          <body name="leg_l3_link" pos="0 -0.01433 -0.0575">
            <inertial pos="0.003163 -0.022552 -0.027258" quat="0.678041 0.0230005 -0.0875592 0.729428" mass="1.39047" diaginertia="0.00722081 0.00694653 0.00181065"/>
            <joint name="leg_l3_joint" pos="0 0 0" axis="0 -1 0" range="-0.8 1.2" frictionloss="0.2"/>
            <geom class="visual" mesh="leg_l3_link"/>
            <geom class="collision" size="0.03 0.125 0.025" pos="0.015 0.02 -0.1" quat="0.707388 0.706825 0 0" type="box"/>
            <body name="leg_l4_link" pos="0 0.0145 -0.24">
              <inertial pos="-0.012044 0.006361 -0.093905" quat="0.696191 0.0388817 0.0714045 0.713237" mass="0.649518" diaginertia="0.00246473 0.00221871 0.000430556"/>
              <joint name="leg_l4_joint" pos="0 0 0" axis="0 1 0" range="0 1.5" frictionloss="0.2"/>
              <geom class="visual" mesh="leg_l4_link"/>
              <geom class="collision" size="0.0205 0.125 0.015" pos="0 0 -0.105" quat="0.707388 0.706825 0 0" type="box"/>
              <geom class="collision" size="0.034 0.035 0.035" pos="-0.011 0.012 -0.079" quat="0.707388 0.706825 0 0" type="box" />
              <body name="leg_l5_link" pos="0.005 0 -0.23995">
                <inertial pos="0.012435 0 -0.015511" quat="0.48854 0.511203 0.511203 0.48854" mass="0.030265" diaginertia="2.5e-05 2.40454e-05 1.95464e-06"/>
                <joint name="leg_l5_joint" pos="0 0 0" axis="0 -1 0" range="-1.1 1.1" frictionloss="0.2"/>
                <geom class="visual" mesh="leg_l5_link"/>
                <geom class="collision" size="0.05005 0.01725 0.00875" pos="0.01503 0 -0.0102" quat="0.707388 0.706825 0 0" type="box" />
                <body name="leg_l_f1_link" pos="0.06 0 -0.007">
                  <inertial pos="0 0 0" mass="0.01" diaginertia="1e-06 1e-06 1e-06"/>
                  <geom class="foot1"/>
                  <geom class="foot2"/>
                  <site name="leg_l_f1_site" pos="0 0 0"/>
                </body>
                <body name="leg_l_f2_link" pos="-0.03 0 -0.007">
                  <inertial pos="0 0 0" mass="0.01" diaginertia="1e-06 1e-06 1e-06"/>
                  <geom class="foot1"/>
                  <geom class="foot2"/>
                  <site name="leg_l_f2_site" pos="0 0 0"/>
                </body>
              </body>
            </body>
          </body>
        </body>
      </body>
      <body name="leg_r1_link" pos="-0.002 -0.09 -0.1035">
        <inertial pos="0.002501 -5.3e-05 -0.002722" quat="0.503556 0.495251 0.527005 0.472677" mass="0.453728" diaginertia="0.000163063 0.000147076 8.18618e-05"/>
        <joint name="leg_r1_joint" pos="0 0 0" axis="1 0 0" range="-0.5 0.2" frictionloss="0.2"/>
        <geom class="visual" mesh="leg_r1_link"/>
        <geom class="collision" size="0.03 0.035 0.0775" pos="-0.019 -0.001 0" quat="0.500398 0.5 0.499602 0.5" type="box"/>
        <body name="leg_r2_link" pos="0 0.00016972 -0.0325">
          <inertial pos="9e-05 -0.043826 -0.058639" quat="0.7074 0.0648812 -0.0612384 0.70116" mass="0.925998" diaginertia="0.00166463 0.00123897 0.0010754"/>
          <joint name="leg_r2_joint" pos="0 0 0" axis="0 0 1" range="-1 0.5" frictionloss="0.2"/>
          <geom class="visual" mesh="leg_r2_link"/>
          <geom class="collision" size="0.065 0.073 0.073" pos="0 -0.0033 -0.057" quat="0.707388 0.706825 0 0" type="box"/>
          <body name="leg_r3_link" pos="0 0.01633 -0.0575">
            <inertial pos="0.003311 0.02265 -0.027271" quat="0.734236 -0.0877978 0.023126 0.672795" mass="1.38862" diaginertia="0.00722344 0.00694292 0.00180965"/>
            <joint name="leg_r3_joint" pos="0 0 0" axis="0 1 0" range="-1.2 0.8" frictionloss="0.2"/>
            <geom class="visual" mesh="leg_r3_link"/>
            <geom class="collision" size="0.03 0.125 0.025" pos="0.015 -0.02 -0.1" quat="0.707388 0.706825 0 0" type="box"/>
            <body name="leg_r4_link" pos="0 -0.0145 -0.24">
              <inertial pos="-0.007886 -0.007123 -0.088091" quat="0.589012 0.00853647 -0.018288 0.807872" mass="0.61472" diaginertia="0.00177827 0.00175932 0.00018341"/>
              <joint name="leg_r4_joint" pos="0 0 0" axis="0 1 0" range="0 1.5" frictionloss="0.2"/>
              <geom class="visual" mesh="leg_r4_link"/>
              <geom class="collision" size="0.0205 0.125 0.015" pos="0 0 -0.105" quat="0.707388 0.706825 0 0" type="box" />
              <geom class="collision" size="0.034 0.035 0.035" pos="-0.011 -0.012 -0.079" quat="0.707388 0.706825 0 0" type="box" />
              <body name="leg_r5_link" pos="0.005 0 -0.23995">
                <inertial pos="0.012435 -0.0005 -0.015511" quat="0.48854 0.511203 0.511203 0.48854" mass="0.030265" diaginertia="2.5e-05 2.40454e-05 1.95464e-06"/>
                <joint name="leg_r5_joint" pos="0 0 0" axis="0 1 0" range="-1.1 1.1" frictionloss="0.2"/>
                <geom class="visual" mesh="leg_r5_link"/>
                <geom class="collision" size="0.05005 0.01725 0.00875" pos="0.01503 0 -0.0102" quat="0.707388 0.706825 0 0" type="box" />
                <body name="leg_r_f1_link" pos="0.06 0 -0.007">
                  <inertial pos="0 0 0" mass="0.01" diaginertia="1e-06 1e-06 1e-06"/>
                  <geom class="foot1"/>
                  <geom class="foot2"/>
                  <site name="leg_r_f1_site" pos="0 0 0"/>
                </body>
                <body name="leg_r_f2_link" pos="-0.03 0 -0.007">
                  <inertial pos="0 0 0" mass="0.01" diaginertia="1e-06 1e-06 1e-06"/>
                  <geom class="foot1"/>
                  <geom class="foot2"/>
                  <site name="leg_r_f2_site" pos="0 0 0"/>
                </body>
              </body>
            </body>
          </body>
        </body>
      </body>
    </body>
  </worldbody>
  
  <actuator>
    <!-- <motor name="leg_l1_joint" joint="leg_l1_joint" gear="1" ctrllimited="true" ctrlrange="-100 100" />
    <motor name="leg_l2_joint" joint="leg_l2_joint" gear="1" ctrllimited="true" ctrlrange="-100 100" />
    <motor name="leg_l3_joint" joint="leg_l3_joint" gear="1" ctrllimited="true" ctrlrange="-100 100" />
    <motor name="leg_l4_joint" joint="leg_l4_joint" gear="1" ctrllimited="true" ctrlrange="-100 100" />
    <motor name="leg_l5_joint" joint="leg_l5_joint" gear="1" ctrllimited="true" ctrlrange="-100 100" />
    <motor name="leg_r1_joint" joint="leg_r1_joint" gear="1" ctrllimited="true" ctrlrange="-100 100" />
    <motor name="leg_r2_joint" joint="leg_r2_joint" gear="1" ctrllimited="true" ctrlrange="-100 100" />
    <motor name="leg_r3_joint" joint="leg_r3_joint" gear="1" ctrllimited="true" ctrlrange="-100 100" />
    <motor name="leg_r4_joint" joint="leg_r4_joint" gear="1" ctrllimited="true" ctrlrange="-100 100" />
    <motor name="leg_r5_joint" joint="leg_r5_joint" gear="1" ctrllimited="true" ctrlrange="-100 100" /> -->
    <position class="hunter" name="leg_l1_joint" joint="leg_l1_joint" forcerange="-40 40" kp="100" kv="3"/>
    <position class="hunter" name="leg_l2_joint" joint="leg_l2_joint" forcerange="-100 100" kp="100" kv="3"/>
    <position class="hunter" name="leg_l3_joint" joint="leg_l3_joint" forcerange="-100 100" kp="100" kv="3"/>
    <position class="hunter" name="leg_l4_joint" joint="leg_l4_joint" forcerange="-40 40" kp="100" kv="3"/>
    <position class="hunter" name="leg_l5_joint" joint="leg_l5_joint" forcerange="-20 20" kp="100" kv="3"/>

    <position class="hunter" name="leg_r1_joint" joint="leg_r1_joint" forcerange="-40 40" kp="100" kv="3"/>
    <position class="hunter" name="leg_r2_joint" joint="leg_r2_joint" forcerange="-100 100" kp="100" kv="3"/>
    <position class="hunter" name="leg_r3_joint" joint="leg_r3_joint" forcerange="-100 100" kp="100" kv="3"/>
    <position class="hunter" name="leg_r4_joint" joint="leg_r4_joint" forcerange="-40 40" kp="100" kv="3"/>
    <position class="hunter" name="leg_r5_joint" joint="leg_r5_joint" forcerange="-20 20" kp="100" kv="3"/>
  </actuator>
  
  <sensor>
    <actuatorpos name='leg_l1_joint_p' actuator='leg_l1_joint' user='13' />
    <actuatorpos name='leg_l2_joint_p' actuator='leg_l2_joint' user='13' />
    <actuatorpos name='leg_l3_joint_p' actuator='leg_l3_joint' user='13' />
    <actuatorpos name='leg_l4_joint_p' actuator='leg_l4_joint' user='13' />
    <actuatorpos name='leg_l5_joint_p' actuator='leg_l5_joint' user='13' />
    <actuatorpos name='leg_r1_joint_p' actuator='leg_r1_joint' user='13' />
    <actuatorpos name='leg_r2_joint_p' actuator='leg_r2_joint' user='13' />
    <actuatorpos name='leg_r3_joint_p' actuator='leg_r3_joint' user='13' />
    <actuatorpos name='leg_r4_joint_p' actuator='leg_r4_joint' user='13' />
    <actuatorpos name='leg_r5_joint_p' actuator='leg_r5_joint' user='13' />

    <actuatorvel name='leg_l1_joint_v' actuator='leg_l1_joint' user='13' />
    <actuatorvel name='leg_l2_joint_v' actuator='leg_l2_joint' user='13' />
    <actuatorvel name='leg_l3_joint_v' actuator='leg_l3_joint' user='13' />
    <actuatorvel name='leg_l4_joint_v' actuator='leg_l4_joint' user='13' />
    <actuatorvel name='leg_l5_joint_v' actuator='leg_l5_joint' user='13' />
    <actuatorvel name='leg_r1_joint_v' actuator='leg_r1_joint' user='13' />
    <actuatorvel name='leg_r2_joint_v' actuator='leg_r2_joint' user='13' />
    <actuatorvel name='leg_r3_joint_v' actuator='leg_r3_joint' user='13' />
    <actuatorvel name='leg_r4_joint_v' actuator='leg_r4_joint' user='13' />
    <actuatorvel name='leg_r5_joint_v' actuator='leg_r5_joint' user='13' />

    <actuatorfrc name='leg_l1_joint_f' actuator='leg_l1_joint' user='13' />
    <actuatorfrc name='leg_l2_joint_f' actuator='leg_l2_joint' user='13' />
    <actuatorfrc name='leg_l3_joint_f' actuator='leg_l3_joint' user='13' />
    <actuatorfrc name='leg_l4_joint_f' actuator='leg_l4_joint' user='13' />
    <actuatorfrc name='leg_l5_joint_f' actuator='leg_l5_joint' user='13' />
    <actuatorfrc name='leg_r1_joint_f' actuator='leg_r1_joint' user='13' />
    <actuatorfrc name='leg_r2_joint_f' actuator='leg_r2_joint' user='13' />
    <actuatorfrc name='leg_r3_joint_f' actuator='leg_r3_joint' user='13' />
    <actuatorfrc name='leg_r4_joint_f' actuator='leg_r4_joint' user='13' />
    <actuatorfrc name='leg_r5_joint_f' actuator='leg_r5_joint' user='13' />


    <gyro site="imu" name="gyro"/>
    <velocimeter site="imu" name="local_linvel"/>
    <accelerometer site="imu" name="accelerometer"/>
    <framepos objtype="site" objname="imu" name="position"/>
    <framezaxis objtype="site" objname="imu" name="upvector"/>
    <framexaxis objtype="site" objname="imu" name="forwardvector"/>
    <framelinvel objtype="site" objname="imu" name="global_linvel"/>
    <frameangvel objtype="site" objname="imu" name="global_angvel"/>
    <framequat objtype="site" objname="imu" name="orientation"/>

  </sensor>
</mujoco>
